[2025-01-26T00:27:23.392+0000] {taskinstance.py:1103} INFO - Dependencies all met for dep_context=non-requeueable deps ti=<TaskInstance: crypto_ingestion_dag.run_ingestion_container manual__2025-01-26T00:22:17.949785+00:00 [queued]>
[2025-01-26T00:27:23.398+0000] {taskinstance.py:1103} INFO - Dependencies all met for dep_context=requeueable deps ti=<TaskInstance: crypto_ingestion_dag.run_ingestion_container manual__2025-01-26T00:22:17.949785+00:00 [queued]>
[2025-01-26T00:27:23.401+0000] {taskinstance.py:1308} INFO - Starting attempt 2 of 2
[2025-01-26T00:27:23.419+0000] {taskinstance.py:1327} INFO - Executing <Task(DockerOperator): run_ingestion_container> on 2025-01-26 00:22:17.949785+00:00
[2025-01-26T00:27:23.425+0000] {standard_task_runner.py:57} INFO - Started process 224 to run task
[2025-01-26T00:27:23.427+0000] {standard_task_runner.py:84} INFO - Running: ['***', 'tasks', 'run', 'crypto_ingestion_dag', 'run_ingestion_container', 'manual__2025-01-26T00:22:17.949785+00:00', '--job-id', '26', '--raw', '--subdir', 'DAGS_FOLDER/crypto_ingestion_dag.py', '--cfg-path', '/tmp/tmpwy6emt94']
[2025-01-26T00:27:23.430+0000] {standard_task_runner.py:85} INFO - Job 26: Subtask run_ingestion_container
[2025-01-26T00:27:23.450+0000] {logging_mixin.py:149} WARNING - /home/***/.local/lib/python3.7/site-packages/***/settings.py:195 DeprecationWarning: The sql_alchemy_conn option in [core] has been moved to the sql_alchemy_conn option in [database] - the old setting has been used, but please update your config.
[2025-01-26T00:27:23.511+0000] {task_command.py:410} INFO - Running <TaskInstance: crypto_ingestion_dag.run_ingestion_container manual__2025-01-26T00:22:17.949785+00:00 [running]> on host b5b03959b0b9
[2025-01-26T00:27:23.592+0000] {taskinstance.py:1547} INFO - Exporting env vars: AIRFLOW_CTX_DAG_OWNER='***' AIRFLOW_CTX_DAG_ID='crypto_ingestion_dag' AIRFLOW_CTX_TASK_ID='run_ingestion_container' AIRFLOW_CTX_EXECUTION_DATE='2025-01-26T00:22:17.949785+00:00' AIRFLOW_CTX_TRY_NUMBER='2' AIRFLOW_CTX_DAG_RUN_ID='manual__2025-01-26T00:22:17.949785+00:00'
[2025-01-26T00:27:23.659+0000] {docker.py:334} INFO - Starting docker container from image ingestion-container:latest
[2025-01-26T00:27:23.686+0000] {docker.py:343} WARNING - Using remote engine or docker-in-docker and mounting temporary volume from host is not supported. Falling back to `mount_tmp_dir=False` mode. You can set `mount_tmp_dir` parameter to False to disable mounting and remove the warning
[2025-01-26T00:27:24.289+0000] {docker.py:403} INFO - Traceback (most recent call last):
  File "/app/data_ingestion.py", line 80, in <module>
    fetch_coingecko_market_data(api_key=api_key, pages=5)
  File "/app/data_ingestion.py", line 18, in fetch_coingecko_market_data
    conn = psycopg2.connect(
  File "/usr/local/lib/python3.10/site-packages/psycopg2/__init__.py", line 122, in connect
[2025-01-26T00:27:24.290+0000] {docker.py:403} INFO - conn = _connect(dsn, connection_factory=connection_factory, **kwasync)
psycopg2.OperationalError: could not translate host name "postgres" to address: Name or service not known
[2025-01-26T00:27:24.460+0000] {taskinstance.py:1824} ERROR - Task failed with exception
Traceback (most recent call last):
  File "/home/airflow/.local/lib/python3.7/site-packages/docker/api/client.py", line 268, in _raise_for_status
    response.raise_for_status()
  File "/home/airflow/.local/lib/python3.7/site-packages/requests/models.py", line 1021, in raise_for_status
    raise HTTPError(http_error_msg, response=self)
requests.exceptions.HTTPError: 400 Client Error: Bad Request for url: http+docker://localhost/v1.47/containers/create

The above exception was the direct cause of the following exception:

Traceback (most recent call last):
  File "/home/airflow/.local/lib/python3.7/site-packages/airflow/providers/docker/operators/docker.py", line 339, in _run_image
    return self._run_image_with_mounts(self.mounts + [tmp_mount], add_tmp_variable=True)
  File "/home/airflow/.local/lib/python3.7/site-packages/airflow/providers/docker/operators/docker.py", line 393, in _run_image_with_mounts
    hostname=self.hostname,
  File "/home/airflow/.local/lib/python3.7/site-packages/docker/api/container.py", line 431, in create_container
    return self.create_container_from_config(config, name, platform)
  File "/home/airflow/.local/lib/python3.7/site-packages/docker/api/container.py", line 448, in create_container_from_config
    return self._result(res, True)
  File "/home/airflow/.local/lib/python3.7/site-packages/docker/api/client.py", line 274, in _result
    self._raise_for_status(response)
  File "/home/airflow/.local/lib/python3.7/site-packages/docker/api/client.py", line 270, in _raise_for_status
    raise create_api_error_from_http_exception(e) from e
  File "/home/airflow/.local/lib/python3.7/site-packages/docker/errors.py", line 39, in create_api_error_from_http_exception
    raise cls(e, response=response, explanation=explanation) from e
docker.errors.APIError: 400 Client Error for http+docker://localhost/v1.47/containers/create: Bad Request ("invalid mount config for type "bind": bind source path does not exist: /host_mnt/private/tmp/airflowtmpr6u9rakj")

During handling of the above exception, another exception occurred:

Traceback (most recent call last):
  File "/home/airflow/.local/lib/python3.7/site-packages/airflow/providers/docker/operators/docker.py", line 478, in execute
    return self._run_image()
  File "/home/airflow/.local/lib/python3.7/site-packages/airflow/providers/docker/operators/docker.py", line 348, in _run_image
    return self._run_image_with_mounts(self.mounts, add_tmp_variable=False)
  File "/home/airflow/.local/lib/python3.7/site-packages/airflow/providers/docker/operators/docker.py", line 412, in _run_image_with_mounts
    raise AirflowException(f"Docker container failed: {repr(result)} lines {joined_log_lines}")
airflow.exceptions.AirflowException: Docker container failed: {'StatusCode': 1} lines Traceback (most recent call last):
  File "/app/data_ingestion.py", line 80, in <module>
    fetch_coingecko_market_data(api_key=api_key, pages=5)
  File "/app/data_ingestion.py", line 18, in fetch_coingecko_market_data
    conn = psycopg2.connect(
  File "/usr/local/lib/python3.10/site-packages/psycopg2/__init__.py", line 122, in connect
conn = _connect(dsn, connection_factory=connection_factory, **kwasync)
psycopg2.OperationalError: could not translate host name "postgres" to address: Name or service not known
[2025-01-26T00:27:24.483+0000] {taskinstance.py:1350} INFO - Marking task as FAILED. dag_id=crypto_ingestion_dag, task_id=run_ingestion_container, execution_date=20250126T002217, start_date=20250126T002723, end_date=20250126T002724
[2025-01-26T00:27:24.494+0000] {standard_task_runner.py:109} ERROR - Failed to execute job 26 for task run_ingestion_container (Docker container failed: {'StatusCode': 1} lines Traceback (most recent call last):
  File "/app/data_ingestion.py", line 80, in <module>
    fetch_coingecko_market_data(api_key=api_key, pages=5)
  File "/app/data_ingestion.py", line 18, in fetch_coingecko_market_data
    conn = psycopg2.connect(
  File "/usr/local/lib/python3.10/site-packages/psycopg2/__init__.py", line 122, in connect
conn = _connect(dsn, connection_factory=connection_factory, **kwasync)
psycopg2.OperationalError: could not translate host name "postgres" to address: Name or service not known; 224)
[2025-01-26T00:27:24.535+0000] {local_task_job_runner.py:225} INFO - Task exited with return code 1
[2025-01-26T00:27:24.563+0000] {taskinstance.py:2653} INFO - 0 downstream tasks scheduled from follow-on schedule check
